Workbook

Sheet ⚙️ SETUP GOOGLE SHEETS
A2: ⚙️ CONFIGURACIÓN INICIAL — GOOGLE SHEETS
A3: Hacé esto UNA SOLA VEZ después de subir el archivo a Google Drive. Tarda 3 minutos.
A5: PASO 1 — Subir a Google Drive
A6: • Andá a drive.google.com
A7: • Arrastrá este archivo (.xlsx) a tu Drive, o usá el botón '+ Nuevo' → 'Subir archivo'.
A8: • Una vez subido, hacé doble clic sobre él.
A9: • Google te va a preguntar cómo abrirlo. Elegí 'Abrir con Google Sheets'.
A11: PASO 2 — Abrir el editor de script
A12: • Con el archivo abierto en Google Sheets, andá a la barra de menú superior.
A13: • Hacé clic en 'Extensiones' (o 'Extensions' si está en inglés).
A14: • Después clic en 'Apps Script'.
A15: • Se abre una pantalla nueva con código. Borrá todo lo que haya ahí (Ctrl+A, Delete).
... A37: 💡 Si cerrás y volvés a abrir el archivo en otro momento, el menú aparece solo. Solo necesitás configurarlo una vez.

Sheet 📖 INSTRUCCIONES
A2: 📖 GUÍA DE USO — CALCULADORA DE COSTOS 360
A3: Seguí estos pasos para costear cualquier receta de forma profesional.
A5: PASO 1 — Actualizá tus ingredientes
A6: • Abrí la hoja 🧂 INGREDIENTES. | H6: co
A7: • Revisá que los precios estén al día. Si cambió el precio de algo, actualizalo ahí.
A8: • Si usás un ingrediente que no está en la lista, agregalo al final con su precio y unidad.
A9: • Las unidades disponibles son: KG, LITRO, UNIDAD
A11: PASO 2 — Completá los datos de la receta
A12: • Abrí la hoja 🧮 CALCULADORA.
A13: • Escribí el nombre de la receta, una descripción opcional y la cantidad de porciones o unidades que rinde.
A14: • La fecha se completa automáticamente.
A16: PASO 3 — Cargá los ingredientes
A17: • En la sección INGREDIENTES, hacé clic en la celda de la columna INGREDIENTE.
A18: • Elegí de la lista desplegable (los datos vienen de tu hoja de ingredientes).
A19: • En la columna CANTIDAD, escribí cuánto usás (en gramos, mililitros o unidades según corresponda).
A20: • El precio de referencia y el costo se calculan solos.
... A42: 🌿 Este archivo es tuyo: podés adaptarlo, agregar ingredientes y personalizar los gastos a tu medida. ¡Mucho éxito con tu emprendimiento! 🧁

Sheet Hoja 2

Sheet 🧂 INGREDIENTES
A2: 🧁 BASE DE INGREDIENTES
A3: Mantené actualizada esta lista para que la calculadora funcione correctamente.
A5: # | B5: INGREDIENTE | C5: PRECIO por KG/L/UNID | D5: UNIDAD | E5: CATEGORÍA | F5: ÚLTIMA ACTUALIZACIÓN | G5: NOTAS
A6: 1 | B6: Harina 0000 | C6: 40 | D6: KG | E6: Básicos | F6: 46194
A7: 2 | B7: Azúcar | C7: 50 | D7: KG | E7: Básicos | F7: 46194
A8: 3 | B8: queso mascarpone | C8: 8500 | D8: KG | E8: Lácteos | F8: 46104
A9: 4 | B9: manteca | C9: 5000 | D9: KG | E9: Lácteos | F9: 46104
A10: 5 | B10: mascarpone | C10: 0 | D10: KG | E10: Lácteos | F10: 46104
A11: 6 | B11: cafe | C11: 0 | D11: KG | E11: Especiales | F11: 46104
A12: 7 | B12: Crema de leche | C12: 200 | D12: LITRO | E12: Lácteos | F12: 46104
A13: 8 | B13: Queso crema | C13: 385 | D13: KG | E13: Lácteos | F13: 46103
A14: 9 | B14: Mermelada | C14: 0 | D14: KG | E14: Especiales | F14: 46103
A15: 10 | B15: Cacao | C15: 260 | D15: KG | E15: Especiales | F15: 46103
A16: 11 | B16: Esencia de vainilla | C16: 0 | D16: LITRO | E16: Esencias | F16: 46103
A17: 12 | B17: leche | C17: 45 | D17: LITRO | E17: Lácteos | F17: 46104
... A39: 34 | B39: galletitas maria | C39: 205 | D39: KG | E39: Básicos | F39: 46103
A40: 35 | B40: chocolate blanco | C40: 210 | D40: KG | E40: chocolate
A41: 36 | B41: Premezcla santa maria | C41: 0 | D41: KG | E41: Basicos | F41: 46103
A42: 37 | B42: chocolate con leche | C42: 0 | D42: KG
A43: 38 | B43: Chocolate Alpino | C43: 210 | D43: KG | E43: chocolate
A44: 39 | B44: Cerezas Marrasquino | C44: 0 | D44: KG | E44: Decoracion
A45: 40 | B45: Azucar Granulada | C45: 0 | D45: KG | E45: Decoracion
A46: 41 | B46: Crema ledevit | C46: 200 | D46: KG | E46: decoracion
A47: 42 | D47: KG
A48: 43 | D48: KG
A49: 44 | D49: KG
A50: 45 | D50: KG
A51: 46 | D51: KG
A52: 47 | D52: KG
A53: 48 | D53: KG
A54: 49 | D54: KG
A55: 50 | D55: KG
A56: 51 | D56: KG
A57: 52 | D57: KG
A58: 53 | D58: KG
... A100: 95 | D100: KG

Sheet 🧮 CALCULADORA
A2: 🧁 CALCULADORA DE COSTOS
A3: Completá los datos de tu receta para conocer el costo real y el precio de venta sugerido.
A5: 📋 DATOS DE LA RECETA
B6: Nombre de la receta: | C6: Chocotorta
B7: Descripción (opcional):
B8: Cantidad que rinde (porciones / unidades):
B9: Fecha: | C9: =TODAY() -> 46226
A11: 🥚 INGREDIENTES DE LA RECETA
A12: # | B12: INGREDIENTE | C12: PRECIO REF. | D12: CANTIDAD | E12: UNIDAD | F12: COSTO
A13: 1 | B13: Chocolinas | C13: =IFERROR(VLOOKUP(B13,'🧂 INGREDIENTES'!$B$6:$D$500,2,0),"") -> 460 | D13: 510 | E13: =IFERROR(VLOOKUP(B13,'🧂 INGREDIENTES'!$B$6:$D$500,3,0),"") -> KG | F13: =IFERROR(IF(C13="","",IF((E13="KG")+(E13="LITRO")+(E13="GR")+(E13="ML"),C13*D13/1000,C13*D13)),"") -> 234.6
A14: 2 | B14: Harina 0000 | C14: =IFERROR(VLOOKUP(B14,'🧂 INGREDIENTES'!$B$6:$D$500,2,0),"") -> 40 | D14: 500 | E14: =IFERROR(VLOOKUP(B14,'🧂 INGREDIENTES'!$B$6:$D$500,3,0),"") -> KG | F14: =IFERROR(IF(C14="","",IF((E14="KG")+(E14="LITRO")+(E14="GR")+(E14="ML"),C14*D14/1000,C14*D14)),"") -> 20
A15: 3 | B15: Manteca | C15: =IFERROR(VLOOKUP(B15,'🧂 INGREDIENTES'!$B$6:$D$500,2,0),"") -> 5000 | D15: 100 | E15: =IFERROR(VLOOKUP(B15,'🧂 INGREDIENTES'!$B$6:$D$500,3,0),"") -> KG | F15: =IFERROR(IF(C15="","",IF((E15="KG")+(E15="LITRO")+(E15="GR")+(E15="ML"),C15*D15/1000,C15*D15)),"") -> 500
A16: 4 | B16: Azúcar | C16: =IFERROR(VLOOKUP(B16,'🧂 INGREDIENTES'!$B$6:$D$500,2,0),"") -> 50 | E16: =IFERROR(VLOOKUP(B16,'🧂 INGREDIENTES'!$B$6:$D$500,3,0),"") -> KG | F16: =IFERROR(IF(C16="","",IF((E16="KG")+(E16="LITRO")+(E16="GR")+(E16="ML"),C16*D16/1000,C16*D16)),"") -> 0
A17: 5 | C17: =IFERROR(VLOOKUP(B17,'🧂 INGREDIENTES'!$B$6:$D$500,2,0),"") | E17: =IFERROR(VLOOKUP(B17,'🧂 INGREDIENTES'!$B$6:$D$500,3,0),"") | F17: =IFERROR(IF(C17="","",IF((E17="KG")+(E17="LITRO")+(E17="GR")+(E17="ML"),C17*D17/1000,C17*D17)),"")
A18: 6 | C18: =IFERROR(VLOOKUP(B18,'🧂 INGREDIENTES'!$B$6:$D$500,2,0),"") | E18: =IFERROR(VLOOKUP(B18,'🧂 INGREDIENTES'!$B$6:$D$500,3,0),"") | F18: =IFERROR(IF(C18="","",IF((E18="KG")+(E18="LITRO")+(E18="GR")+(E18="ML"),C18*D18/1000,C18*D18)),"")
A19: 7 | C19: =IFERROR(VLOOKUP(B19,'🧂 INGREDIENTES'!$B$6:$D$500,2,0),"") | E19: =IFERROR(VLOOKUP(B19,'🧂 INGREDIENTES'!$B$6:$D$500,3,0),"") | F19: =IFERROR(IF(C19="","",IF((E19="KG")+(E19="LITRO")+(E19="GR")+(E19="ML"),C19*D19/1000,C19*D19)),"")
A20: =A19+1 -> 8 | C20: =IFERROR(VLOOKUP(B20,'🧂 INGREDIENTES'!$B$6:$D$500,2,0),"") | E20: =IFERROR(VLOOKUP(B20,'🧂 INGREDIENTES'!$B$6:$D$500,3,0),"") | F20: =IFERROR(IF(C20="","",IF((E20="KG")+(E20="LITRO")+(E20="GR")+(E20="ML"),C20*D20/1000,C20*D20)),"")
A21: =A20+1 -> 9 | C21: =IFERROR(VLOOKUP(B21,'🧂 INGREDIENTES'!$B$6:$D$500,2,0),"") | E21: =IFERROR(VLOOKUP(B21,'🧂 INGREDIENTES'!$B$6:$D$500,3,0),"") | F21: =IFERROR(IF(C21="","",IF((E21="KG")+(E21="LITRO")+(E21="GR")+(E21="ML"),C21*D21/1000,C21*D21)),"")
A22: =A21+1 -> 10 | C22: =IFERROR(VLOOKUP(B22,'🧂 INGREDIENTES'!$B$6:$D$500,2,0),"") | E22: =IFERROR(VLOOKUP(B22,'🧂 INGREDIENTES'!$B$6:$D$500,3,0),"") | F22: =IFERROR(IF(C22="","",IF((E22="KG")+(E22="LITRO")+(E22="GR")+(E22="ML"),C22*D22/1000,C22*D22)),"")
A23: =A22+1 -> 11 | C23: =IFERROR(VLOOKUP(B23,'🧂 INGREDIENTES'!$B$6:$D$500,2,0),"") | E23: =IFERROR(VLOOKUP(B23,'🧂 INGREDIENTES'!$B$6:$D$500,3,0),"") | F23: =IFERROR(IF(C23="","",IF((E23="KG")+(E23="LITRO")+(E23="GR")+(E23="ML"),C23*D23/1000,C23*D23)),"")
A24: =A23+1 -> 12 | C24: =IFERROR(VLOOKUP(B24,'🧂 INGREDIENTES'!$B$6:$D$500,2,0),"") | E24: =IFERROR(VLOOKUP(B24,'🧂 INGREDIENTES'!$B$6:$D$500,3,0),"") | F24: =IFERROR(IF(C24="","",IF((E24="KG")+(E24="LITRO")+(E24="GR")+(E24="ML"),C24*D24/1000,C24*D24)),"")
A25: =A24+1 -> 13 | C25: =IFERROR(VLOOKUP(B25,'🧂 INGREDIENTES'!$B$6:$D$500,2,0),"") | E25: =IFERROR(VLOOKUP(B25,'🧂 INGREDIENTES'!$B$6:$D$500,3,0),"") | F25: =IFERROR(IF(C25="","",IF((E25="KG")+(E25="LITRO")+(E25="GR")+(E25="ML"),C25*D25/1000,C25*D25)),"")
A26: =A25+1 -> 14 | C26: =IFERROR(VLOOKUP(B26,'🧂 INGREDIENTES'!$B$6:$D$500,2,0),"") | E26: =IFERROR(VLOOKUP(B26,'🧂 INGREDIENTES'!$B$6:$D$500,3,0),"") | F26: =IFERROR(IF(C26="","",IF((E26="KG")+(E26="LITRO")+(E26="GR")+(E26="ML"),C26*D26/1000,C26*D26)),"")
A27: =A26+1 -> 15 | C27: =IFERROR(VLOOKUP(B27,'🧂 INGREDIENTES'!$B$6:$D$500,2,0),"") | E27: =IFERROR(VLOOKUP(B27,'🧂 INGREDIENTES'!$B$6:$D$500,3,0),"") | F27: =IFERROR(IF(C27="","",IF((E27="KG")+(E27="LITRO")+(E27="GR")+(E27="ML"),C27*D27/1000,C27*D27)),"")
A28: =A27+1 -> 16 | C28: =IFERROR(VLOOKUP(B28,'🧂 INGREDIENTES'!$B$6:$D$500,2,0),"") | E28: =IFERROR(VLOOKUP(B28,'🧂 INGREDIENTES'!$B$6:$D$500,3,0),"") | F28: =IFERROR(IF(C28="","",IF((E28="KG")+(E28="LITRO")+(E28="GR")+(E28="ML"),C28*D28/1000,C28*D28)),"")
A29: =A28+1 -> 17 | C29: =IFERROR(VLOOKUP(B29,'🧂 INGREDIENTES'!$B$6:$D$500,2,0),"") | E29: =IFERROR(VLOOKUP(B29,'🧂 INGREDIENTES'!$B$6:$D$500,3,0),"") | F29: =IFERROR(IF(C29="","",IF((E29="KG")+(E29="LITRO")+(E29="GR")+(E29="ML"),C29*D29/1000,C29*D29)),"")
A30: =A29+1 -> 18 | C30: =IFERROR(VLOOKUP(B30,'🧂 INGREDIENTES'!$B$6:$D$500,2,0),"") | E30: =IFERROR(VLOOKUP(B30,'🧂 INGREDIENTES'!$B$6:$D$500,3,0),"") | F30: =IFERROR(IF(C30="","",IF((E30="KG")+(E30="LITRO")+(E30="GR")+(E30="ML"),C30*D30/1000,C30*D30)),"")
A31: =A30+1 -> 19 | C31: =IFERROR(VLOOKUP(B31,'🧂 INGREDIENTES'!$B$6:$D$500,2,0),"") | E31: =IFERROR(VLOOKUP(B31,'🧂 INGREDIENTES'!$B$6:$D$500,3,0),"") | F31: =IFERROR(IF(C31="","",IF((E31="KG")+(E31="LITRO")+(E31="GR")+(E31="ML"),C31*D31/1000,C31*D31)),"")
... A41: =A40+1 -> 29 | C41: =IFERROR(VLOOKUP(B41,'🧂 INGREDIENTES'!$B$6:$D$500,2,0),"") | E41: =IFERROR(VLOOKUP(B41,'🧂 INGREDIENTES'!$B$6:$D$500,3,0),"") | F41: =IFERROR(IF(C41="","",IF((E41="KG")+(E41="LITRO")+(E41="GR")+(E41="ML"),C41*D41/1000,C41*D41)),"")
A42: SUBTOTAL INGREDIENTES | F42: =SUM(F13:F41) -> 754.6
A44: 👩‍🍳 MANO DE OBRA
A45: # | B45: CONCEPTO | D45: HORAS | E45: $ x HORA | F45: COSTO
A46: 1 | B46: mano | D46: 2 | E46: 0 | F46: =IFERROR(IF(D46="","",D46*E46),"") -> 0
A47: 2 | F47: =IFERROR(IF(D47="","",D47*E47),"")
A48: 3 | F48: =IFERROR(IF(D48="","",D48*E48),"")
A49: 4 | F49: =IFERROR(IF(D49="","",D49*E49),"")
A50: 5 | F50: =IFERROR(IF(D50="","",D50*E50),"")
A51: SUBTOTAL MANO DE OBRA | F51: =SUM(F46:F50) -> 0
A53: 📦 PACKAGING Y GASTOS EXTRAS
A54: # | B54: TIPO DE GASTO | C54: CONCEPTO / DETALLE | E54: MONTO | F54: SUBTOTAL
...

Sheet 📚 RECETAS GUARDADAS
A1: por fa
A2: 📚 RECETAS GUARDADAS
A3: Los precios de venta se actualizan automáticamente cuando modificás los precios en la hoja INGREDIENTES.
A5: # | B5: NOMBRE DE RECETA | C5: FECHA | D5: PORCIONES | E5: COSTO INGREDIENTES | F5: COSTO MANO DE OBRA | G5: GASTOS EXTRAS | H5: COSTO TOTAL | I5: % MARGEN | J5: ⭐ PRECIO DE VENTA | K5: NOTAS
A6: =ROW()-5 -> 1 | B6: Chocotorta | C6: 46225.531 | E6: 754.6 | F6: 0 | G6: 125 | H6: 879.6 | I6: 1 | J6: #VALUE!
A7: =ROW()-5 -> 2
A8: =ROW()-5 -> 3 | B8: =IF('⚙️ DETALLE TÉCNICO'!M227="","",'⚙️ DETALLE TÉCNICO'!M227) | C8: =IF('⚙️ DETALLE TÉCNICO'!M227="","",'⚙️ DETALLE TÉCNICO'!N227) | D8: =IF('⚙️ DETALLE TÉCNICO'!M227="","",'⚙️ DETALLE TÉCNICO'!L227) | E8: =IF('⚙️ DETALLE TÉCNICO'!M227="","",IFERROR(SUMPRODUCT(IFERROR(IF(('⚙️ DETALLE TÉCNICO'!E227:E246="KG")+('⚙️ DETALLE TÉCNICO'!E227:E246="LITRO")+('⚙️ DETALLE TÉCNICO'!E227:E246="GR")+('⚙️ DETALLE TÉCNICO'!E227:E246="ML"),IFERROR(VLOOKUP('⚙️ DETALLE TÉCNICO'!C227:C246,'🧂 INGREDIENTES'!$B$6:$C$500,2,0),0)*'⚙️ DETALLE TÉCNICO'!D227:D246/1000,IFERROR(VLOOKUP('⚙️ DETALLE TÉCNICO'!C227:C246,'🧂 INGREDIENTES'!$B$6:$C$500,2,0),0)*'⚙️ DETALLE TÉCNICO'!D227:D246),0)),0)) | F8: =IF('⚙️ DETALLE TÉCNICO'!M227="","",IFERROR(SUMPRODUCT(IFERROR('⚙️ DETALLE TÉCNICO'!G227:G231*'⚙️ DETALLE TÉCNICO'!H227:H231,0)),0)) | G8: =IF('⚙️ DETALLE TÉCNICO'!M227="","",IFERROR(SUM('⚙️ DETALLE TÉCNICO'!J227:J234),0)) | H8: =IF('⚙️ DETALLE TÉCNICO'!M227="","",E8+F8+G8) | I8: =IF('⚙️ DETALLE TÉCNICO'!M227="","",'⚙️ DETALLE TÉCNICO'!K227) | J8: =IF('⚙️ DETALLE TÉCNICO'!M227="","",H8*(1+I8))
A9: =ROW()-5 -> 4 | B9: =IF('⚙️ DETALLE TÉCNICO'!M247="","",'⚙️ DETALLE TÉCNICO'!M247) | C9: =IF('⚙️ DETALLE TÉCNICO'!M247="","",'⚙️ DETALLE TÉCNICO'!N247) | D9: =IF('⚙️ DETALLE TÉCNICO'!M247="","",'⚙️ DETALLE TÉCNICO'!L247) | E9: =IF('⚙️ DETALLE TÉCNICO'!M247="","",IFERROR(SUMPRODUCT(IFERROR(IF(('⚙️ DETALLE TÉCNICO'!E247:E266="KG")+('⚙️ DETALLE TÉCNICO'!E247:E266="LITRO")+('⚙️ DETALLE TÉCNICO'!E247:E266="GR")+('⚙️ DETALLE TÉCNICO'!E247:E266="ML"),IFERROR(VLOOKUP('⚙️ DETALLE TÉCNICO'!C247:C266,'🧂 INGREDIENTES'!$B$6:$C$500,2,0),0)*'⚙️ DETALLE TÉCNICO'!D247:D266/1000,IFERROR(VLOOKUP('⚙️ DETALLE TÉCNICO'!C247:C266,'🧂 INGREDIENTES'!$B$6:$C$500,2,0),0)*'⚙️ DETALLE TÉCNICO'!D247:D266),0)),0)) | F9: =IF('⚙️ DETALLE TÉCNICO'!M247="","",IFERROR(SUMPRODUCT(IFERROR('⚙️ DETALLE TÉCNICO'!G247:G251*'⚙️ DETALLE TÉCNICO'!H247:H251,0)),0)) | G9: =IF('⚙️ DETALLE TÉCNICO'!M247="","",IFERROR(SUM('⚙️ DETALLE TÉCNICO'!J247:J254),0)) | H9: =IF('⚙️ DETALLE TÉCNICO'!M247="","",E9+F9+G9) | I9: =IF('⚙️ DETALLE TÉCNICO'!M247="","",'⚙️ DETALLE TÉCNICO'!K247) | J9: =IF('⚙️ DETALLE TÉCNICO'!M247="","",H9*(1+I9))
A10: =ROW()-5 -> 5 | B10: =IF('⚙️ DETALLE TÉCNICO'!M267="","",'⚙️ DETALLE TÉCNICO'!M267) | C10: =IF('⚙️ DETALLE TÉCNICO'!M267="","",'⚙️ DETALLE TÉCNICO'!N267) | D10: =IF('⚙️ DETALLE TÉCNICO'!M267="","",'⚙️ DETALLE TÉCNICO'!L267) | E10: =IF('⚙️ DETALLE TÉCNICO'!M267="","",IFERROR(SUMPRODUCT(IFERROR(IF(('⚙️ DETALLE TÉCNICO'!E267:E286="KG")+('⚙️ DETALLE TÉCNICO'!E267:E286="LITRO")+('⚙️ DETALLE TÉCNICO'!E267:E286="GR")+('⚙️ DETALLE TÉCNICO'!E267:E286="ML"),IFERROR(VLOOKUP('⚙️ DETALLE TÉCNICO'!C267:C286,'🧂 INGREDIENTES'!$B$6:$C$500,2,0),0)*'⚙️ DETALLE TÉCNICO'!D267:D286/1000,IFERROR(VLOOKUP('⚙️ DETALLE TÉCNICO'!C267:C286,'🧂 INGREDIENTES'!$B$6:$C$500,2,0),0)*'⚙️ DETALLE TÉCNICO'!D267:D286),0)),0)) | F10: =IF('⚙️ DETALLE TÉCNICO'!M267="","",IFERROR(SUMPRODUCT(IFERROR('⚙️ DETALLE TÉCNICO'!G267:G271*'⚙️ DETALLE TÉCNICO'!H267:H271,0)),0)) | G10: =IF('⚙️ DETALLE TÉCNICO'!M267="","",IFERROR(SUM('⚙️ DETALLE TÉCNICO'!J267:J274),0)) | H10: =IF('⚙️ DETALLE TÉCNICO'!M267="","",E10+F10+G10) | I10: =IF('⚙️ DETALLE TÉCNICO'!M267="","",'⚙️ DETALLE TÉCNICO'!K267) | J10: =IF('⚙️ DETALLE TÉCNICO'!M267="","",H10*(1+I10))
A11: =ROW()-5 -> 6 | B11: =IF('⚙️ DETALLE TÉCNICO'!M287="","",'⚙️ DETALLE TÉCNICO'!M287) | C11: =IF('⚙️ DETALLE TÉCNICO'!M287="","",'⚙️ DETALLE TÉCNICO'!N287) | D11: =IF('⚙️ DETALLE TÉCNICO'!M287="","",'⚙️ DETALLE TÉCNICO'!L287) | E11: =IF('⚙️ DETALLE TÉCNICO'!M287="","",IFERROR(SUMPRODUCT(IFERROR(IF(('⚙️ DETALLE TÉCNICO'!E287:E306="KG")+('⚙️ DETALLE TÉCNICO'!E287:E306="LITRO")+('⚙️ DETALLE TÉCNICO'!E287:E306="GR")+('⚙️ DETALLE TÉCNICO'!E287:E306="ML"),IFERROR(VLOOKUP('⚙️ DETALLE TÉCNICO'!C287:C306,'🧂 INGREDIENTES'!$B$6:$C$500,2,0),0)*'⚙️ DETALLE TÉCNICO'!D287:D306/1000,IFERROR(VLOOKUP('⚙️ DETALLE TÉCNICO'!C287:C306,'🧂 INGREDIENTES'!$B$6:$C$500,2,0),0)*'⚙️ DETALLE TÉCNICO'!D287:D306),0)),0)) | F11: =IF('⚙️ DETALLE TÉCNICO'!M287="","",IFERROR(SUMPRODUCT(IFERROR('⚙️ DETALLE TÉCNICO'!G287:G291*'⚙️ DETALLE TÉCNICO'!H287:H291,0)),0)) | G11: =IF('⚙️ DETALLE TÉCNICO'!M287="","",IFERROR(SUM('⚙️ DETALLE TÉCNICO'!J287:J294),0)) | H11: =IF('⚙️ DETALLE TÉCNICO'!M287="","",E11+F11+G11) | I11: =IF('⚙️ DETALLE TÉCNICO'!M287="","",'⚙️ DETALLE TÉCNICO'!K287) | J11: =IF('⚙️ DETALLE TÉCNICO'!M287="","",H11*(1+I11))
A12: =ROW()-5 -> 7 | B12: =IF('⚙️ DETALLE TÉCNICO'!M307="","",'⚙️ DETALLE TÉCNICO'!M307) | C12: =IF('⚙️ DETALLE TÉCNICO'!M307="","",'⚙️ DETALLE TÉCNICO'!N307) | D12: =IF('⚙️ DETALLE TÉCNICO'!M307="","",'⚙️ DETALLE TÉCNICO'!L307) | E12: =IF('⚙️ DETALLE TÉCNICO'!M307="","",IFERROR(SUMPRODUCT(IFERROR(IF(('⚙️ DETALLE TÉCNICO'!E307:E326="KG")+('⚙️ DETALLE TÉCNICO'!E307:E326="LITRO")+('⚙️ DETALLE TÉCNICO'!E307:E326="GR")+('⚙️ DETALLE TÉCNICO'!E307:E326="ML"),IFERROR(VLOOKUP('⚙️ DETALLE TÉCNICO'!C307:C326,'🧂 INGREDIENTES'!$B$6:$C$500,2,0),0)*'⚙️ DETALLE TÉCNICO'!D307:D326/1000,IFERROR(VLOOKUP('⚙️ DETALLE TÉCNICO'!C307:C326,'🧂 INGREDIENTES'!$B$6:$C$500,2,0),0)*'⚙️ DETALLE TÉCNICO'!D307:D326),0)),0)) | F12: =IF('⚙️ DETALLE TÉCNICO'!M307="","",IFERROR(SUMPRODUCT(IFERROR('⚙️ DETALLE TÉCNICO'!G307:G311*'⚙️ DETALLE TÉCNICO'!H307:H311,0)),0)) | G12: =IF('⚙️ DETALLE TÉCNICO'!M307="","",IFERROR(SUM('⚙️ DETALLE TÉCNICO'!J307:J314),0)) | H12: =IF('⚙️ DETALLE TÉCNICO'!M307="","",E12+F12+G12) | I12: =IF('⚙️ DETALLE TÉCNICO'!M307="","",'⚙️ DETALLE TÉCNICO'!K307) | J12: =IF('⚙️ DETALLE TÉCNICO'!M307="","",H12*(1+I12))
A13: =ROW()-5 -> 8 | B13: =IF('⚙️ DETALLE TÉCNICO'!M327="","",'⚙️ DETALLE TÉCNICO'!M327) | C13: =IF('⚙️ DETALLE TÉCNICO'!M327="","",'⚙️ DETALLE TÉCNICO'!N327) | D13: =IF('⚙️ DETALLE TÉCNICO'!M327="","",'⚙️ DETALLE TÉCNICO'!L327) | E13: =IF('⚙️ DETALLE TÉCNICO'!M327="","",IFERROR(SUMPRODUCT(IFERROR(IF(('⚙️ DETALLE TÉCNICO'!E327:E346="KG")+('⚙️ DETALLE TÉCNICO'!E327:E346="LITRO")+('⚙️ DETALLE TÉCNICO'!E327:E346="GR")+('⚙️ DETALLE TÉCNICO'!E327:E346="ML"),IFERROR(VLOOKUP('⚙️ DETALLE TÉCNICO'!C327:C346,'🧂 INGREDIENTES'!$B$6:$C$500,2,0),0)*'⚙️ DETALLE TÉCNICO'!D327:D346/1000,IFERROR(VLOOKUP('⚙️ DETALLE TÉCNICO'!C327:C346,'🧂 INGREDIENTES'!$B$6:$C$500,2,0),0)*'⚙️ DETALLE TÉCNICO'!D327:D346),0)),0)) | F13: =IF('⚙️ DETALLE TÉCNICO'!M327="","",IFERROR(SUMPRODUCT(IFERROR('⚙️ DETALLE TÉCNICO'!G327:G331*'⚙️ DETALLE TÉCNICO'!H327:H331,0)),0)) | G13: =IF('⚙️ DETALLE TÉCNICO'!M327="","",IFERROR(SUM('⚙️ DETALLE TÉCNICO'!J327:J334),0)) | H13: =IF('⚙️ DETALLE TÉCNICO'!M327="","",E13+F13+G13) | I13: =IF('⚙️ DETALLE TÉCNICO'!M327="","",'⚙️ DETALLE TÉCNICO'!K327) | J13: =IF('⚙️ DETALLE TÉCNICO'!M327="","",H13*(1+I13))
A14: =ROW()-5 -> 9 | B14: =IF('⚙️ DETALLE TÉCNICO'!M347="","",'⚙️ DETALLE TÉCNICO'!M347) | C14: =IF('⚙️ DETALLE TÉCNICO'!M347="","",'⚙️ DETALLE TÉCNICO'!N347) | D14: =IF('⚙️ DETALLE TÉCNICO'!M347="","",'⚙️ DETALLE TÉCNICO'!L347) | E14: =IF('⚙️ DETALLE TÉCNICO'!M347="","",IFERROR(SUMPRODUCT(IFERROR(IF(('⚙️ DETALLE TÉCNICO'!E347:E366="KG")+('⚙️ DETALLE TÉCNICO'!E347:E366="LITRO")+('⚙️ DETALLE TÉCNICO'!E347:E366="GR")+('⚙️ DETALLE TÉCNICO'!E347:E366="ML"),IFERROR(VLOOKUP('⚙️ DETALLE TÉCNICO'!C347:C366,'🧂 INGREDIENTES'!$B$6:$C$500,2,0),0)*'⚙️ DETALLE TÉCNICO'!D347:D366/1000,IFERROR(VLOOKUP('⚙️ DETALLE TÉCNICO'!C347:C366,'🧂 INGREDIENTES'!$B$6:$C$500,2,0),0)*'⚙️ DETALLE TÉCNICO'!D347:D366),0)),0)) | F14: =IF('⚙️ DETALLE TÉCNICO'!M347="","",IFERROR(SUMPRODUCT(IFERROR('⚙️ DETALLE TÉCNICO'!G347:G351*'⚙️ DETALLE TÉCNICO'!H347:H351,0)),0)) | G14: =IF('⚙️ DETALLE TÉCNICO'!M347="","",IFERROR(SUM('⚙️ DETALLE TÉCNICO'!J347:J354),0)) | H14: =IF('⚙️ DETALLE TÉCNICO'!M347="","",E14+F14+G14) | I14: =IF('⚙️ DETALLE TÉCNICO'!M347="","",'⚙️ DETALLE TÉCNICO'!K347) | J14: =IF('⚙️ DETALLE TÉCNICO'!M347="","",H14*(1+I14))
A15: =ROW()-5 -> 10 | B15: =IF('⚙️ DETALLE TÉCNICO'!M367="","",'⚙️ DETALLE TÉCNICO'!M367) | C15: =IF('⚙️ DETALLE TÉCNICO'!M367="","",'⚙️ DETALLE TÉCNICO'!N367) | D15: =IF('⚙️ DETALLE TÉCNICO'!M367="","",'⚙️ DETALLE TÉCNICO'!L367) | E15: =IF('⚙️ DETALLE TÉCNICO'!M367="","",IFERROR(SUMPRODUCT(IFERROR(IF(('⚙️ DETALLE TÉCNICO'!E367:E386="KG")+('⚙️ DETALLE TÉCNICO'!E367:E386="LITRO")+('⚙️ DETALLE TÉCNICO'!E367:E386="GR")+('⚙️ DETALLE TÉCNICO'!E367:E386="ML"),IFERROR(VLOOKUP('⚙️ DETALLE TÉCNICO'!C367:C386,'🧂 INGREDIENTES'!$B$6:$C$500,2,0),0)*'⚙️ DETALLE TÉCNICO'!D367:D386/1000,IFERROR(VLOOKUP('⚙️ DETALLE TÉCNICO'!C367:C386,'🧂 INGREDIENTES'!$B$6:$C$500,2,0),0)*'⚙️ DETALLE TÉCNICO'!D367:D386),0)),0)) | F15: =IF('⚙️ DETALLE TÉCNICO'!M367="","",IFERROR(SUMPRODUCT(IFERROR('⚙️ DETALLE TÉCNICO'!G367:G371*'⚙️ DETALLE TÉCNICO'!H367:H371,0)),0)) | G15: =IF('⚙️ DETALLE TÉCNICO'!M367="","",IFERROR(SUM('⚙️ DETALLE TÉCNICO'!J367:J374),0)) | H15: =IF('⚙️ DETALLE TÉCNICO'!M367="","",E15+F15+G15) | I15: =IF('⚙️ DETALLE TÉCNICO'!M367="","",'⚙️ DETALLE TÉCNICO'!K367) | J15: =IF('⚙️ DETALLE TÉCNICO'!M367="","",H15*(1+I15))
A16: =ROW()-5 -> 11 | B16: =IF('⚙️ DETALLE TÉCNICO'!M387="","",'⚙️ DETALLE TÉCNICO'!M387) | C16: =IF('⚙️ DETALLE TÉCNICO'!M387="","",'⚙️ DETALLE TÉCNICO'!N387) | D16: =IF('⚙️ DETALLE TÉCNICO'!M387="","",'⚙️ DETALLE TÉCNICO'!L387) | E16: =IF('⚙️ DETALLE TÉCNICO'!M387="","",IFERROR(SUMPRODUCT(IFERROR(IF(('⚙️ DETALLE TÉCNICO'!E387:E406="KG")+('⚙️ DETALLE TÉCNICO'!E387:E406="LITRO")+('⚙️ DETALLE TÉCNICO'!E387:E406="GR")+('⚙️ DETALLE TÉCNICO'!E387:E406="ML"),IFERROR(VLOOKUP('⚙️ DETALLE TÉCNICO'!C387:C406,'🧂 INGREDIENTES'!$B$6:$C$500,2,0),0)*'⚙️ DETALLE TÉCNICO'!D387:D406/1000,IFERROR(VLOOKUP('⚙️ DETALLE TÉCNICO'!C387:C406,'🧂 INGREDIENTES'!$B$6:$C$500,2,0),0)*'⚙️ DETALLE TÉCNICO'!D387:D406),0)),0)) | F16: =IF('⚙️ DETALLE TÉCNICO'!M387="","",IFERROR(SUMPRODUCT(IFERROR('⚙️ DETALLE TÉCNICO'!G387:G391*'⚙️ DETALLE TÉCNICO'!H387:H391,0)),0)) | G16: =IF('⚙️ DETALLE TÉCNICO'!M387="","",IFERROR(SUM('⚙️ DETALLE TÉCNICO'!J387:J394),0)) | H16: =IF('⚙️ DETALLE TÉCNICO'!M387="","",E16+F16+G16) | I16: =IF('⚙️ DETALLE TÉCNICO'!M387="","",'⚙️ DETALLE TÉCNICO'!K387) | J16: =IF('⚙️ DETALLE TÉCNICO'!M387="","",H16*(1+I16))
A17: =ROW()-5 -> 12 | B17: =IF('⚙️ DETALLE TÉCNICO'!M407="","",'⚙️ DETALLE TÉCNICO'!M407) | C17: =IF('⚙️ DETALLE TÉCNICO'!M407="","",'⚙️ DETALLE TÉCNICO'!N407) | D17: =IF('⚙️ DETALLE TÉCNICO'!M407="","",'⚙️ DETALLE TÉCNICO'!L407) | E17: =IF('⚙️ DETALLE TÉCNICO'!M407="","",IFERROR(SUMPRODUCT(IFERROR(IF(('⚙️ DETALLE TÉCNICO'!E407:E426="KG")+('⚙️ DETALLE TÉCNICO'!E407:E426="LITRO")+('⚙️ DETALLE TÉCNICO'!E407:E426="GR")+('⚙️ DETALLE TÉCNICO'!E407:E426="ML"),IFERROR(VLOOKUP('⚙️ DETALLE TÉCNICO'!C407:C426,'🧂 INGREDIENTES'!$B$6:$C$500,2,0),0)*'⚙️ DETALLE TÉCNICO'!D407:D426/1000,IFERROR(VLOOKUP('⚙️ DETALLE TÉCNICO'!C407:C426,'🧂 INGREDIENTES'!$B$6:$C$500,2,0),0)*'⚙️ DETALLE TÉCNICO'!D407:D426),0)),0)) | F17: =IF('⚙️ DETALLE TÉCNICO'!M407="","",IFERROR(SUMPRODUCT(IFERROR('⚙️ DETALLE TÉCNICO'!G407:G411*'⚙️ DETALLE TÉCNICO'!H407:H411,0)),0)) | G17: =IF('⚙️ DETALLE TÉCNICO'!M407="","",IFERROR(SUM('⚙️ DETALLE TÉCNICO'!J407:J414),0)) | H17: =IF('⚙️ DETALLE TÉCNICO'!M407="","",E17+F17+G17) | I17: =IF('⚙️ DETALLE TÉCNICO'!M407="","",'⚙️ DETALLE TÉCNICO'!K407) | J17: =IF('⚙️ DETALLE TÉCNICO'!M407="","",H17*(1+I17))
A18: =ROW()-5 -> 13 | B18: =IF('⚙️ DETALLE TÉCNICO'!M427="","",'⚙️ DETALLE TÉCNICO'!M427) | C18: =IF('⚙️ DETALLE TÉCNICO'!M427="","",'⚙️ DETALLE TÉCNICO'!N427) | D18: =IF('⚙️ DETALLE TÉCNICO'!M427="","",'⚙️ DETALLE TÉCNICO'!L427) | E18: =IF('⚙️ DETALLE TÉCNICO'!M427="","",IFERROR(SUMPRODUCT(IFERROR(IF(('⚙️ DETALLE TÉCNICO'!E427:E446="KG")+('⚙️ DETALLE TÉCNICO'!E427:E446="LITRO")+('⚙️ DETALLE TÉCNICO'!E427:E446="GR")+('⚙️ DETALLE TÉCNICO'!E427:E446="ML"),IFERROR(VLOOKUP('⚙️ DETALLE TÉCNICO'!C427:C446,'🧂 INGREDIENTES'!$B$6:$C$500,2,0),0)*'⚙️ DETALLE TÉCNICO'!D427:D446/1000,IFERROR(VLOOKUP('⚙️ DETALLE TÉCNICO'!C427:C446,'🧂 INGREDIENTES'!$B$6:$C$500,2,0),0)*'⚙️ DETALLE TÉCNICO'!D427:D446),0)),0)) | F18: =IF('⚙️ DETALLE TÉCNICO'!M427="","",IFERROR(SUMPRODUCT(IFERROR('⚙️ DETALLE TÉCNICO'!G427:G431*'⚙️ DETALLE TÉCNICO'!H427:H431,0)),0)) | G18: =IF('⚙️ DETALLE TÉCNICO'!M427="","",IFERROR(SUM('⚙️ DETALLE TÉCNICO'!J427:J434),0)) | H18: =IF('⚙️ DETALLE TÉCNICO'!M427="","",E18+F18+G18) | I18: =IF('⚙️ DETALLE TÉCNICO'!M427="","",'⚙️ DETALLE TÉCNICO'!K427) | J18: =IF('⚙️ DETALLE TÉCNICO'!M427="","",H18*(1+I18))
A19: =ROW()-5 -> 14 | B19: =IF('⚙️ DETALLE TÉCNICO'!M447="","",'⚙️ DETALLE TÉCNICO'!M447) | C19: =IF('⚙️ DETALLE TÉCNICO'!M447="","",'⚙️ DETALLE TÉCNICO'!N447) | D19: =IF('⚙️ DETALLE TÉCNICO'!M447="","",'⚙️ DETALLE TÉCNICO'!L447) | E19: =IF('⚙️ DETALLE TÉCNICO'!M447="","",IFERROR(SUMPRODUCT(IFERROR(IF(('⚙️ DETALLE TÉCNICO'!E447:E466="KG")+('⚙️ DETALLE TÉCNICO'!E447:E466="LITRO")+('⚙️ DETALLE TÉCNICO'!E447:E466="GR")+('⚙️ DETALLE TÉCNICO'!E447:E466="ML"),IFERROR(VLOOKUP('⚙️ DETALLE TÉCNICO'!C447:C466,'🧂 INGREDIENTES'!$B$6:$C$500,2,0),0)*'⚙️ DETALLE TÉCNICO'!D447:D466/1000,IFERROR(VLOOKUP('⚙️ DETALLE TÉCNICO'!C447:C466,'🧂 INGREDIENTES'!$B$6:$C$500,2,0),0)*'⚙️ DETALLE TÉCNICO'!D447:D466),0)),0)) | F19: =IF('⚙️ DETALLE TÉCNICO'!M447="","",IFERROR(SUMPRODUCT(IFERROR('⚙️ DETALLE TÉCNICO'!G447:G451*'⚙️ DETALLE TÉCNICO'!H447:H451,0)),0)) | G19: =IF('⚙️ DETALLE TÉCNICO'!M447="","",IFERROR(SUM('⚙️ DETALLE TÉCNICO'!J447:J454),0)) | H19: =IF('⚙️ DETALLE TÉCNICO'!M447="","",E19+F19+G19) | I19: =IF('⚙️ DETALLE TÉCNICO'!M447="","",'⚙️ DETALLE TÉCNICO'!K447) | J19: =IF('⚙️ DETALLE TÉCNICO'!M447="","",H19*(1+I19))
A20: =ROW()-5 -> 15 | B20: =IF('⚙️ DETALLE TÉCNICO'!M467="","",'⚙️ DETALLE TÉCNICO'!M467) | C20: =IF('⚙️ DETALLE TÉCNICO'!M467="","",'⚙️ DETALLE TÉCNICO'!N467) | D20: =IF('⚙️ DETALLE TÉCNICO'!M467="","",'⚙️ DETALLE TÉCNICO'!L467) | E20: =IF('⚙️ DETALLE TÉCNICO'!M467="","",IFERROR(SUMPRODUCT(IFERROR(IF(('⚙️ DETALLE TÉCNICO'!E467:E486="KG")+('⚙️ DETALLE TÉCNICO'!E467:E486="LITRO")+('⚙️ DETALLE TÉCNICO'!E467:E486="GR")+('⚙️ DETALLE TÉCNICO'!E467:E486="ML"),IFERROR(VLOOKUP('⚙️ DETALLE TÉCNICO'!C467:C486,'🧂 INGREDIENTES'!$B$6:$C$500,2,0),0)*'⚙️ DETALLE TÉCNICO'!D467:D486/1000,IFERROR(VLOOKUP('⚙️ DETALLE TÉCNICO'!C467:C486,'🧂 INGREDIENTES'!$B$6:$C$500,2,0),0)*'⚙️ DETALLE TÉCNICO'!D467:D486),0)),0)) | F20: =IF('⚙️ DETALLE TÉCNICO'!M467="","",IFERROR(SUMPRODUCT(IFERROR('⚙️ DETALLE TÉCNICO'!G467:G471*'⚙️ DETALLE TÉCNICO'!H467:H471,0)),0)) | G20: =IF('⚙️ DETALLE TÉCNICO'!M467="","",IFERROR(SUM('⚙️ DETALLE TÉCNICO'!J467:J474),0)) | H20: =IF('⚙️ DETALLE TÉCNICO'!M467="","",E20+F20+G20) | I20: =IF('⚙️ DETALLE TÉCNICO'!M467="","",'⚙️ DETALLE TÉCNICO'!K467) | J20: =IF('⚙️ DETALLE TÉCNICO'!M467="","",H20*(1+I20))
A21: =ROW()-5 -> 16 | B21: =IF('⚙️ DETALLE TÉCNICO'!M487="","",'⚙️ DETALLE TÉCNICO'!M487) | C21: =IF('⚙️ DETALLE TÉCNICO'!M487="","",'⚙️ DETALLE TÉCNICO'!N487) | D21: =IF('⚙️ DETALLE TÉCNICO'!M487="","",'⚙️ DETALLE TÉCNICO'!L487) | E21: =IF('⚙️ DETALLE TÉCNICO'!M487="","",IFERROR(SUMPRODUCT(IFERROR(IF(('⚙️ DETALLE TÉCNICO'!E487:E506="KG")+('⚙️ DETALLE TÉCNICO'!E487:E506="LITRO")+('⚙️ DETALLE TÉCNICO'!E487:E506="GR")+('⚙️ DETALLE TÉCNICO'!E487:E506="ML"),IFERROR(VLOOKUP('⚙️ DETALLE TÉCNICO'!C487:C506,'🧂 INGREDIENTES'!$B$6:$C$500,2,0),0)*'⚙️ DETALLE TÉCNICO'!D487:D506/1000,IFERROR(VLOOKUP('⚙️ DETALLE TÉCNICO'!C487:C506,'🧂 INGREDIENTES'!$B$6:$C$500,2,0),0)*'⚙️ DETALLE TÉCNICO'!D487:D506),0)),0)) | F21: =IF('⚙️ DETALLE TÉCNICO'!M487="","",IFERROR(SUMPRODUCT(IFERROR('⚙️ DETALLE TÉCNICO'!G487:G491*'⚙️ DETALLE TÉCNICO'!H487:H491,0)),0)) | G21: =IF('⚙️ DETALLE TÉCNICO'!M487="","",IFERROR(SUM('⚙️ DETALLE TÉCNICO'!J487:J494),0)) | H21: =IF('⚙️ DETALLE TÉCNICO'!M487="","",E21+F21+G21) | I21: =IF('⚙️ DETALLE TÉCNICO'!M487="","",'⚙️ DETALLE TÉCNICO'!K487) | J21: =IF('⚙️ DETALLE TÉCNICO'!M487="","",H21*(1+I21))
A22: =ROW()-5 -> 17 | B22: =IF('⚙️ DETALLE TÉCNICO'!M507="","",'⚙️ DETALLE TÉCNICO'!M507) | C22: =IF('⚙️ DETALLE TÉCNICO'!M507="","",'⚙️ DETALLE TÉCNICO'!N507) | D22: =IF('⚙️ DETALLE TÉCNICO'!M507="","",'⚙️ DETALLE TÉCNICO'!L507) | E22: =IF('⚙️ DETALLE TÉCNICO'!M507="","",IFERROR(SUMPRODUCT(IFERROR(IF(('⚙️ DETALLE TÉCNICO'!E507:E526="KG")+('⚙️ DETALLE TÉCNICO'!E507:E526="LITRO")+('⚙️ DETALLE TÉCNICO'!E507:E526="GR")+('⚙️ DETALLE TÉCNICO'!E507:E526="ML"),IFERROR(VLOOKUP('⚙️ DETALLE TÉCNICO'!C507:C526,'🧂 INGREDIENTES'!$B$6:$C$500,2,0),0)*'⚙️ DETALLE TÉCNICO'!D507:D526/1000,IFERROR(VLOOKUP('⚙️ DETALLE TÉCNICO'!C507:C526,'🧂 INGREDIENTES'!$B$6:$C$500,2,0),0)*'⚙️ DETALLE TÉCNICO'!D507:D526),0)),0)) | F22: =IF('⚙️ DETALLE TÉCNICO'!M507="","",IFERROR(SUMPRODUCT(IFERROR('⚙️ DETALLE TÉCNICO'!G507:G511*'⚙️ DETALLE TÉCNICO'!H507:H511,0)),0)) | G22: =IF('⚙️ DETALLE TÉCNICO'!M507="","",IFERROR(SUM('⚙️ DETALLE TÉCNICO'!J507:J514),0)) | H22: =IF('⚙️ DETALLE TÉCNICO'!M507="","",E22+F22+G22) | I22: =IF('⚙️ DETALLE TÉCNICO'!M507="","",'⚙️ DETALLE TÉCNICO'!K507) | J22: =IF('⚙️ DETALLE TÉCNICO'!M507="","",H22*(1+I22))
A23: =ROW()-5 -> 18 | B23: =IF('⚙️ DETALLE TÉCNICO'!M527="","",'⚙️ DETALLE TÉCNICO'!M527) | C23: =IF('⚙️ DETALLE TÉCNICO'!M527="","",'⚙️ DETALLE TÉCNICO'!N527) | D23: =IF('⚙️ DETALLE TÉCNICO'!M527="","",'⚙️ DETALLE TÉCNICO'!L527) | E23: =IF('⚙️ DETALLE TÉCNICO'!M527="","",IFERROR(SUMPRODUCT(IFERROR(IF(('⚙️ DETALLE TÉCNICO'!E527:E546="KG")+('⚙️ DETALLE TÉCNICO'!E527:E546="LITRO")+('⚙️ DETALLE TÉCNICO'!E527:E546="GR")+('⚙️ DETALLE TÉCNICO'!E527:E546="ML"),IFERROR(VLOOKUP('⚙️ DETALLE TÉCNICO'!C527:C546,'🧂 INGREDIENTES'!$B$6:$C$500,2,0),0)*'⚙️ DETALLE TÉCNICO'!D527:D546/1000,IFERROR(VLOOKUP('⚙️ DETALLE TÉCNICO'!C527:C546,'🧂 INGREDIENTES'!$B$6:$C$500,2,0),0)*'⚙️ DETALLE TÉCNICO'!D527:D546),0)),0)) | F23: =IF('⚙️ DETALLE TÉCNICO'!M527="","",IFERROR(SUMPRODUCT(IFERROR('⚙️ DETALLE TÉCNICO'!G527:G531*'⚙️ DETALLE TÉCNICO'!H527:H531,0)),0)) | G23: =IF('⚙️ DETALLE TÉCNICO'!M527="","",IFERROR(SUM('⚙️ DETALLE TÉCNICO'!J527:J534),0)) | H23: =IF('⚙️ DETALLE TÉCNICO'!M527="","",E23+F23+G23) | I23: =IF('⚙️ DETALLE TÉCNICO'!M527="","",'⚙️ DETALLE TÉCNICO'!K527) | J23: =IF('⚙️ DETALLE TÉCNICO'!M527="","",H23*(1+I23))
A24: =ROW()-5 -> 19 | B24: =IF('⚙️ DETALLE TÉCNICO'!M547="","",'⚙️ DETALLE TÉCNICO'!M547) | C24: =IF('⚙️ DETALLE TÉCNICO'!M547="","",'⚙️ DETALLE TÉCNICO'!N547) | D24: =IF('⚙️ DETALLE TÉCNICO'!M547="","",'⚙️ DETALLE TÉCNICO'!L547) | E24: =IF('⚙️ DETALLE TÉCNICO'!M547="","",IFERROR(SUMPRODUCT(IFERROR(IF(('⚙️ DETALLE TÉCNICO'!E547:E566="KG")+('⚙️ DETALLE TÉCNICO'!E547:E566="LITRO")+('⚙️ DETALLE TÉCNICO'!E547:E566="GR")+('⚙️ DETALLE TÉCNICO'!E547:E566="ML"),IFERROR(VLOOKUP('⚙️ DETALLE TÉCNICO'!C547:C566,'🧂 INGREDIENTES'!$B$6:$C$500,2,0),0)*'⚙️ DETALLE TÉCNICO'!D547:D566/1000,IFERROR(VLOOKUP('⚙️ DETALLE TÉCNICO'!C547:C566,'🧂 INGREDIENTES'!$B$6:$C$500,2,0),0)*'⚙️ DETALLE TÉCNICO'!D547:D566),0)),0)) | F24: =IF('⚙️ DETALLE TÉCNICO'!M547="","",IFERROR(SUMPRODUCT(IFERROR('⚙️ DETALLE TÉCNICO'!G547:G551*'⚙️ DETALLE TÉCNICO'!H547:H551,0)),0)) | G24: =IF('⚙️ DETALLE TÉCNICO'!M547="","",IFERROR(SUM('⚙️ DETALLE TÉCNICO'!J547:J554),0)) | H24: =IF('⚙️ DETALLE TÉCNICO'!M547="","",E24+F24+G24) | I24: =IF('⚙️ DETALLE TÉCNICO'!M547="","",'⚙️ DETALLE TÉCNICO'!K547) | J24: =IF('⚙️ DETALLE TÉCNICO'!M547="","",H24*(1+I24))
A25: =ROW()-5 -> 20 | B25: =IF('⚙️ DETALLE TÉCNICO'!M567="","",'⚙️ DETALLE TÉCNICO'!M567) | C25: =IF('⚙️ DETALLE TÉCNICO'!M567="","",'⚙️ DETALLE TÉCNICO'!N567) | D25: =IF('⚙️ DETALLE TÉCNICO'!M567="","",'⚙️ DETALLE TÉCNICO'!L567) | E25: =IF('⚙️ DETALLE TÉCNICO'!M567="","",IFERROR(SUMPRODUCT(IFERROR(IF(('⚙️ DETALLE TÉCNICO'!E567:E586="KG")+('⚙️ DETALLE TÉCNICO'!E567:E586="LITRO")+('⚙️ DETALLE TÉCNICO'!E567:E586="GR")+('⚙️ DETALLE TÉCNICO'!E567:E586="ML"),IFERROR(VLOOKUP('⚙️ DETALLE TÉCNICO'!C567:C586,'🧂 INGREDIENTES'!$B$6:$C$500,2,0),0)*'⚙️ DETALLE TÉCNICO'!D567:D586/1000,IFERROR(VLOOKUP('⚙️ DETALLE TÉCNICO'!C567:C586,'🧂 INGREDIENTES'!$B$6:$C$500,2,0),0)*'⚙️ DETALLE TÉCNICO'!D567:D586),0)),0)) | F25: =IF('⚙️ DETALLE TÉCNICO'!M567="","",IFERROR(SUMPRODUCT(IFERROR('⚙️ DETALLE TÉCNICO'!G567:G571*'⚙️ DETALLE TÉCNICO'!H567:H571,0)),0)) | G25: =IF('⚙️ DETALLE TÉCNICO'!M567="","",IFERROR(SUM('⚙️ DETALLE TÉCNICO'!J567:J574),0)) | H25: =IF('⚙️ DETALLE TÉCNICO'!M567="","",E25+F25+G25) | I25: =IF('⚙️ DETALLE TÉCNICO'!M567="","",'⚙️ DETALLE TÉCNICO'!K567) | J25: =IF('⚙️ DETALLE TÉCNICO'!M567="","",H25*(1+I25))
A26: =ROW()-5 -> 21 | B26: =IF('⚙️ DETALLE TÉCNICO'!M587="","",'⚙️ DETALLE TÉCNICO'!M587) | C26: =IF('⚙️ DETALLE TÉCNICO'!M587="","",'⚙️ DETALLE TÉCNICO'!N587) | D26: =IF('⚙️ DETALLE TÉCNICO'!M587="","",'⚙️ DETALLE TÉCNICO'!L587) | E26: =IF('⚙️ DETALLE TÉCNICO'!M587="","",IFERROR(SUMPRODUCT(IFERROR(IF(('⚙️ DETALLE TÉCNICO'!E587:E606="KG")+('⚙️ DETALLE TÉCNICO'!E587:E606="LITRO")+('⚙️ DETALLE TÉCNICO'!E587:E606="GR")+('⚙️ DETALLE TÉCNICO'!E587:E606="ML"),IFERROR(VLOOKUP('⚙️ DETALLE TÉCNICO'!C587:C606,'🧂 INGREDIENTES'!$B$6:$C$500,2,0),0)*'⚙️ DETALLE TÉCNICO'!D587:D606/1000,IFERROR(VLOOKUP('⚙️ DETALLE TÉCNICO'!C587:C606,'🧂 INGREDIENTES'!$B$6:$C$500,2,0),0)*'⚙️ DETALLE TÉCNICO'!D587:D606),0)),0)) | F26: =IF('⚙️ DETALLE TÉCNICO'!M587="","",IFERROR(SUMPRODUCT(IFERROR('⚙️ DETALLE TÉCNICO'!G587:G591*'⚙️ DETALLE TÉCNICO'!H587:H591,0)),0)) | G26: =IF('⚙️ DETALLE TÉCNICO'!M587="","",IFERROR(SUM('⚙️ DETALLE TÉCNICO'!J587:J594),0)) | H26: =IF('⚙️ DETALLE TÉCNICO'!M587="","",E26+F26+G26) | I26: =IF('⚙️ DETALLE TÉCNICO'!M587="","",'⚙️ DETALLE TÉCNICO'!K587) | J26: =IF('⚙️ DETALLE TÉCNICO'!M587="","",H26*(1+I26))
A27: =ROW()-5 -> 22 | B27: =IF('⚙️ DETALLE TÉCNICO'!M607="","",'⚙️ DETALLE TÉCNICO'!M607) | C27: =IF('⚙️ DETALLE TÉCNICO'!M607="","",'⚙️ DETALLE TÉCNICO'!N607) | D27: =IF('⚙️ DETALLE TÉCNICO'!M607="","",'⚙️ DETALLE TÉCNICO'!L607) | E27: =IF('⚙️ DETALLE TÉCNICO'!M607="","",IFERROR(SUMPRODUCT(IFERROR(IF(('⚙️ DETALLE TÉCNICO'!E607:E626="KG")+('⚙️ DETALLE TÉCNICO'!E607:E626="LITRO")+('⚙️ DETALLE TÉCNICO'!E607:E626="GR")+('⚙️ DETALLE TÉCNICO'!E607:E626="ML"),IFERROR(VLOOKUP('⚙️ DETALLE TÉCNICO'!C607:C626,'🧂 INGREDIENTES'!$B$6:$C$500,2,0),0)*'⚙️ DETALLE TÉCNICO'!D607:D626/1000,IFERROR(VLOOKUP('⚙️ DETALLE TÉCNICO'!C607:C626,'🧂 INGREDIENTES'!$B$6:$C$500,2,0),0)*'⚙️ DETALLE TÉCNICO'!D607:D626),0)),0)) | F27: =IF('⚙️ DETALLE TÉCNICO'!M607="","",IFERROR(SUMPRODUCT(IFERROR('⚙️ DETALLE TÉCNICO'!G607:G611*'⚙️ DETALLE TÉCNICO'!H607:H611,0)),0)) | G27: =IF('⚙️ DETALLE TÉCNICO'!M607="","",IFERROR(SUM('⚙️ DETALLE TÉCNICO'!J607:J614),0)) | H27: =IF('⚙️ DETALLE TÉCNICO'!M607="","",E27+F27+G27) | I27: =IF('⚙️ DETALLE TÉCNICO'!M607="","",'⚙️ DETALLE TÉCNICO'!K607) | J27: =IF('⚙️ DETALLE TÉCNICO'!M607="","",H27*(1+I27))
A28: =ROW()-5 -> 23 | B28: =IF('⚙️ DETALLE TÉCNICO'!M627="","",'⚙️ DETALLE TÉCNICO'!M627) | C28: =IF('⚙️ DETALLE TÉCNICO'!M627="","",'⚙️ DETALLE TÉCNICO'!N627) | D28: =IF('⚙️ DETALLE TÉCNICO'!M627="","",'⚙️ DETALLE TÉCNICO'!L627) | E28: =IF('⚙️ DETALLE TÉCNICO'!M627="","",IFERROR(SUMPRODUCT(IFERROR(IF(('⚙️ DETALLE TÉCNICO'!E627:E646="KG")+('⚙️ DETALLE TÉCNICO'!E627:E646="LITRO")+('⚙️ DETALLE TÉCNICO'!E627:E646="GR")+('⚙️ DETALLE TÉCNICO'!E627:E646="ML"),IFERROR(VLOOKUP('⚙️ DETALLE TÉCNICO'!C627:C646,'🧂 INGREDIENTES'!$B$6:$C$500,2,0),0)*'⚙️ DETALLE TÉCNICO'!D627:D646/1000,IFERROR(VLOOKUP('⚙️ DETALLE TÉCNICO'!C627:C646,'🧂 INGREDIENTES'!$B$6:$C$500,2,0),0)*'⚙️ DETALLE TÉCNICO'!D627:D646),0)),0)) | F28: =IF('⚙️ DETALLE TÉCNICO'!M627="","",IFERROR(SUMPRODUCT(IFERROR('⚙️ DETALLE TÉCNICO'!G627:G631*'⚙️ DETALLE TÉCNICO'!H627:H631,0)),0)) | G28: =IF('⚙️ DETALLE TÉCNICO'!M627="","",IFERROR(SUM('⚙️ DETALLE TÉCNICO'!J627:J634),0)) | H28: =IF('⚙️ DETALLE TÉCNICO'!M627="","",E28+F28+G28) | I28: =IF('⚙️ DETALLE TÉCNICO'!M627="","",'⚙️ DETALLE TÉCNICO'!K627) | J28: =IF('⚙️ DETALLE TÉCNICO'!M627="","",H28*(1+I28))
A29: =ROW()-5 -> 24 | B29: =IF('⚙️ DETALLE TÉCNICO'!M647="","",'⚙️ DETALLE TÉCNICO'!M647) | C29: =IF('⚙️ DETALLE TÉCNICO'!M647="","",'⚙️ DETALLE TÉCNICO'!N647) | D29: =IF('⚙️ DETALLE TÉCNICO'!M647="","",'⚙️ DETALLE TÉCNICO'!L647) | E29: =IF('⚙️ DETALLE TÉCNICO'!M647="","",IFERROR(SUMPRODUCT(IFERROR(IF(('⚙️ DETALLE TÉCNICO'!E647:E666="KG")+('⚙️ DETALLE TÉCNICO'!E647:E666="LITRO")+('⚙️ DETALLE TÉCNICO'!E647:E666="GR")+('⚙️ DETALLE TÉCNICO'!E647:E666="ML"),IFERROR(VLOOKUP('⚙️ DETALLE TÉCNICO'!C647:C666,'🧂 INGREDIENTES'!$B$6:$C$500,2,0),0)*'⚙️ DETALLE TÉCNICO'!D647:D666/1000,IFERROR(VLOOKUP('⚙️ DETALLE TÉCNICO'!C647:C666,'🧂 INGREDIENTES'!$B$6:$C$500,2,0),0)*'⚙️ DETALLE TÉCNICO'!D647:D666),0)),0)) | F29: =IF('⚙️ DETALLE TÉCNICO'!M647="","",IFERROR(SUMPRODUCT(IFERROR('⚙️ DETALLE TÉCNICO'!G647:G651*'⚙️ DETALLE TÉCNICO'!H647:H651,0)),0)) | G29: =IF('⚙️ DETALLE TÉCNICO'!M647="","",IFERROR(SUM('⚙️ DETALLE TÉCNICO'!J647:J654),0)) | H29: =IF('⚙️ DETALLE TÉCNICO'!M647="","",E29+F29+G29) | I29: =IF('⚙️ DETALLE TÉCNICO'!M647="","",'⚙️ DETALLE TÉCNICO'!K647) | J29: =IF('⚙️ DETALLE TÉCNICO'!M647="","",H29*(1+I29))
A30: =ROW()-5 -> 25 | B30: =IF('⚙️ DETALLE TÉCNICO'!M667="","",'⚙️ DETALLE TÉCNICO'!M667) | C30: =IF('⚙️ DETALLE TÉCNICO'!M667="","",'⚙️ DETALLE TÉCNICO'!N667) | D30: =IF('⚙️ DETALLE TÉCNICO'!M667="","",'⚙️ DETALLE TÉCNICO'!L667) | E30: =IF('⚙️ DETALLE TÉCNICO'!M667="","",IFERROR(SUMPRODUCT(IFERROR(IF(('⚙️ DETALLE TÉCNICO'!E667:E686="KG")+('⚙️ DETALLE TÉCNICO'!E667:E686="LITRO")+('⚙️ DETALLE TÉCNICO'!E667:E686="GR")+('⚙️ DETALLE TÉCNICO'!E667:E686="ML"),IFERROR(VLOOKUP('⚙️ DETALLE TÉCNICO'!C667:C686,'🧂 INGREDIENTES'!$B$6:$C$500,2,0),0)*'⚙️ DETALLE TÉCNICO'!D667:D686/1000,IFERROR(VLOOKUP('⚙️ DETALLE TÉCNICO'!C667:C686,'🧂 INGREDIENTES'!$B$6:$C$500,2,0),0)*'⚙️ DETALLE TÉCNICO'!D667:D686),0)),0)) | F30: =IF('⚙️ DETALLE TÉCNICO'!M667="","",IFERROR(SUMPRODUCT(IFERROR('⚙️ DETALLE TÉCNICO'!G667:G671*'⚙️ DETALLE TÉCNICO'!H667:H671,0)),0)) | G30: =IF('⚙️ DETALLE TÉCNICO'!M667="","",IFERROR(SUM('⚙️ DETALLE TÉCNICO'!J667:J674),0)) | H30: =IF('⚙️ DETALLE TÉCNICO'!M667="","",E30+F30+G30) | I30: =IF('⚙️ DETALLE TÉCNICO'!M667="","",'⚙️ DETALLE TÉCNICO'!K667) | J30: =IF('⚙️ DETALLE TÉCNICO'!M667="","",H30*(1+I30))
A31: =ROW()-5 -> 26 | B31: =IF('⚙️ DETALLE TÉCNICO'!M687="","",'⚙️ DETALLE TÉCNICO'!M687) | C31: =IF('⚙️ DETALLE TÉCNICO'!M687="","",'⚙️ DETALLE TÉCNICO'!N687) | D31: =IF('⚙️ DETALLE TÉCNICO'!M687="","",'⚙️ DETALLE TÉCNICO'!L687) | E31: =IF('⚙️ DETALLE TÉCNICO'!M687="","",IFERROR(SUMPRODUCT(IFERROR(IF(('⚙️ DETALLE TÉCNICO'!E687:E706="KG")+('⚙️ DETALLE TÉCNICO'!E687:E706="LITRO")+('⚙️ DETALLE TÉCNICO'!E687:E706="GR")+('⚙️ DETALLE TÉCNICO'!E687:E706="ML"),IFERROR(VLOOKUP('⚙️ DETALLE TÉCNICO'!C687:C706,'🧂 INGREDIENTES'!$B$6:$C$500,2,0),0)*'⚙️ DETALLE TÉCNICO'!D687:D706/1000,IFERROR(VLOOKUP('⚙️ DETALLE TÉCNICO'!C687:C706,'🧂 INGREDIENTES'!$B$6:$C$500,2,0),0)*'⚙️ DETALLE TÉCNICO'!D687:D706),0)),0)) | F31: =IF('⚙️ DETALLE TÉCNICO'!M687="","",IFERROR(SUMPRODUCT(IFERROR('⚙️ DETALLE TÉCNICO'!G687:G691*'⚙️ DETALLE TÉCNICO'!H687:H691,0)),0)) | G31: =IF('⚙️ DETALLE TÉCNICO'!M687="","",IFERROR(SUM('⚙️ DETALLE TÉCNICO'!J687:J694),0)) | H31: =IF('⚙️ DETALLE TÉCNICO'!M687="","",E31+F31+G31) | I31: =IF('⚙️ DETALLE TÉCNICO'!M687="","",'⚙️ DETALLE TÉCNICO'!K687) | J31: =IF('⚙️ DETALLE TÉCNICO'!M687="","",H31*(1+I31))
A32: =ROW()-5 -> 27 | B32: =IF('⚙️ DETALLE TÉCNICO'!M707="","",'⚙️ DETALLE TÉCNICO'!M707) | C32: =IF('⚙️ DETALLE TÉCNICO'!M707="","",'⚙️ DETALLE TÉCNICO'!N707) | D32: =IF('⚙️ DETALLE TÉCNICO'!M707="","",'⚙️ DETALLE TÉCNICO'!L707) | E32: =IF('⚙️ DETALLE TÉCNICO'!M707="","",IFERROR(SUMPRODUCT(IFERROR(IF(('⚙️ DETALLE TÉCNICO'!E707:E726="KG")+('⚙️ DETALLE TÉCNICO'!E707:E726="LITRO")+('⚙️ DETALLE TÉCNICO'!E707:E726="GR")+('⚙️ DETALLE TÉCNICO'!E707:E726="ML"),IFERROR(VLOOKUP('⚙️ DETALLE TÉCNICO'!C707:C726,'🧂 INGREDIENTES'!$B$6:$C$500,2,0),0)*'⚙️ DETALLE TÉCNICO'!D707:D726/1000,IFERROR(VLOOKUP('⚙️ DETALLE TÉCNICO'!C707:C726,'🧂 INGREDIENTES'!$B$6:$C$500,2,0),0)*'⚙️ DETALLE TÉCNICO'!D707:D726),0)),0)) | F32: =IF('⚙️ DETALLE TÉCNICO'!M707="","",IFERROR(SUMPRODUCT(IFERROR('⚙️ DETALLE TÉCNICO'!G707:G711*'⚙️ DETALLE TÉCNICO'!H707:H711,0)),0)) | G32: =IF('⚙️ DETALLE TÉCNICO'!M707="","",IFERROR(SUM('⚙️ DETALLE TÉCNICO'!J707:J714),0)) | H32: =IF('⚙️ DETALLE TÉCNICO'!M707="","",E32+F32+G32) | I32: =IF('⚙️ DETALLE TÉCNICO'!M707="","",'⚙️ DETALLE TÉCNICO'!K707) | J32: =IF('⚙️ DETALLE TÉCNICO'!M707="","",H32*(1+I32))
A33: =ROW()-5 -> 28 | B33: =IF('⚙️ DETALLE TÉCNICO'!M727="","",'⚙️ DETALLE TÉCNICO'!M727) | C33: =IF('⚙️ DETALLE TÉCNICO'!M727="","",'⚙️ DETALLE TÉCNICO'!N727) | D33: =IF('⚙️ DETALLE TÉCNICO'!M727="","",'⚙️ DETALLE TÉCNICO'!L727) | E33: =IF('⚙️ DETALLE TÉCNICO'!M727="","",IFERROR(SUMPRODUCT(IFERROR(IF(('⚙️ DETALLE TÉCNICO'!E727:E746="KG")+('⚙️ DETALLE TÉCNICO'!E727:E746="LITRO")+('⚙️ DETALLE TÉCNICO'!E727:E746="GR")+('⚙️ DETALLE TÉCNICO'!E727:E746="ML"),IFERROR(VLOOKUP('⚙️ DETALLE TÉCNICO'!C727:C746,'🧂 INGREDIENTES'!$B$6:$C$500,2,0),0)*'⚙️ DETALLE TÉCNICO'!D727:D746/1000,IFERROR(VLOOKUP('⚙️ DETALLE TÉCNICO'!C727:C746,'🧂 INGREDIENTES'!$B$6:$C$500,2,0),0)*'⚙️ DETALLE TÉCNICO'!D727:D746),0)),0)) | F33: =IF('⚙️ DETALLE TÉCNICO'!M727="","",IFERROR(SUMPRODUCT(IFERROR('⚙️ DETALLE TÉCNICO'!G727:G731*'⚙️ DETALLE TÉCNICO'!H727:H731,0)),0)) | G33: =IF('⚙️ DETALLE TÉCNICO'!M727="","",IFERROR(SUM('⚙️ DETALLE TÉCNICO'!J727:J734),0)) | H33: =IF('⚙️ DETALLE TÉCNICO'!M727="","",E33+F33+G33) | I33: =IF('⚙️ DETALLE TÉCNICO'!M727="","",'⚙️ DETALLE TÉCNICO'!K727) | J33: =IF('⚙️ DETALLE TÉCNICO'!M727="","",H33*(1+I33))
A34: =ROW()-5 -> 29 | B34: =IF('⚙️ DETALLE TÉCNICO'!M747="","",'⚙️ DETALLE TÉCNICO'!M747) | C34: =IF('⚙️ DETALLE TÉCNICO'!M747="","",'⚙️ DETALLE TÉCNICO'!N747) | D34: =IF('⚙️ DETALLE TÉCNICO'!M747="","",'⚙️ DETALLE TÉCNICO'!L747) | E34: =IF('⚙️ DETALLE TÉCNICO'!M747="","",IFERROR(SUMPRODUCT(IFERROR(IF(('⚙️ DETALLE TÉCNICO'!E747:E766="KG")+('⚙️ DETALLE TÉCNICO'!E747:E766="LITRO")+('⚙️ DETALLE TÉCNICO'!E747:E766="GR")+('⚙️ DETALLE TÉCNICO'!E747:E766="ML"),IFERROR(VLOOKUP('⚙️ DETALLE TÉCNICO'!C747:C766,'🧂 INGREDIENTES'!$B$6:$C$500,2,0),0)*'⚙️ DETALLE TÉCNICO'!D747:D766/1000,IFERROR(VLOOKUP('⚙️ DETALLE TÉCNICO'!C747:C766,'🧂 INGREDIENTES'!$B$6:$C$500,2,0),0)*'⚙️ DETALLE TÉCNICO'!D747:D766),0)),0)) | F34: =IF('⚙️ DETALLE TÉCNICO'!M747="","",IFERROR(SUMPRODUCT(IFERROR('⚙️ DETALLE TÉCNICO'!G747:G751*'⚙️ DETALLE TÉCNICO'!H747:H751,0)),0)) | G34: =IF('⚙️ DETALLE TÉCNICO'!M747="","",IFERROR(SUM('⚙️ DETALLE TÉCNICO'!J747:J754),0)) | H34: =IF('⚙️ DETALLE TÉCNICO'!M747="","",E34+F34+G34) | I34: =IF('⚙️ DETALLE TÉCNICO'!M747="","",'⚙️ DETALLE TÉCNICO'!K747) | J34: =IF('⚙️ DETALLE TÉCNICO'!M747="","",H34*(1+I34))
A35: =ROW()-5 -> 30 | B35: =IF('⚙️ DETALLE TÉCNICO'!M767="","",'⚙️ DETALLE TÉCNICO'!M767) | C35: =IF('⚙️ DETALLE TÉCNICO'!M767="","",'⚙️ DETALLE TÉCNICO'!N767) | D35: =IF('⚙️ DETALLE TÉCNICO'!M767="","",'⚙️ DETALLE TÉCNICO'!L767) | E35: =IF('⚙️ DETALLE TÉCNICO'!M767="","",IFERROR(SUMPRODUCT(IFERROR(IF(('⚙️ DETALLE TÉCNICO'!E767:E786="KG")+('⚙️ DETALLE TÉCNICO'!E767:E786="LITRO")+('⚙️ DETALLE TÉCNICO'!E767:E786="GR")+('⚙️ DETALLE TÉCNICO'!E767:E786="ML"),IFERROR(VLOOKUP('⚙️ DETALLE TÉCNICO'!C767:C786,'🧂 INGREDIENTES'!$B$6:$C$500,2,0),0)*'⚙️ DETALLE TÉCNICO'!D767:D786/1000,IFERROR(VLOOKUP('⚙️ DETALLE TÉCNICO'!C767:C786,'🧂 INGREDIENTES'!$B$6:$C$500,2,0),0)*'⚙️ DETALLE TÉCNICO'!D767:D786),0)),0)) | F35: =IF('⚙️ DETALLE TÉCNICO'!M767="","",IFERROR(SUMPRODUCT(IFERROR('⚙️ DETALLE TÉCNICO'!G767:G771*'⚙️ DETALLE TÉCNICO'!H767:H771,0)),0)) | G35: =IF('⚙️ DETALLE TÉCNICO'!M767="","",IFERROR(SUM('⚙️ DETALLE TÉCNICO'!J767:J774),0)) | H35: =IF('⚙️ DETALLE TÉCNICO'!M767="","",E35+F35+G35) | I35: =IF('⚙️ DETALLE TÉCNICO'!M767="","",'⚙️ DETALLE TÉCNICO'!K767) | J35: =IF('⚙️ DETALLE TÉCNICO'!M767="","",H35*(1+I35))
A36: =ROW()-5 -> 31 | B36: =IF('⚙️ DETALLE TÉCNICO'!M787="","",'⚙️ DETALLE TÉCNICO'!M787) | C36: =IF('⚙️ DETALLE TÉCNICO'!M787="","",'⚙️ DETALLE TÉCNICO'!N787) | D36: =IF('⚙️ DETALLE TÉCNICO'!M787="","",'⚙️ DETALLE TÉCNICO'!L787) | E36: =IF('⚙️ DETALLE TÉCNICO'!M787="","",IFERROR(SUMPRODUCT(IFERROR(IF(('⚙️ DETALLE TÉCNICO'!E787:E806="KG")+('⚙️ DETALLE TÉCNICO'!E787:E806="LITRO")+('⚙️ DETALLE TÉCNICO'!E787:E806="GR")+('⚙️ DETALLE TÉCNICO'!E787:E806="ML"),IFERROR(VLOOKUP('⚙️ DETALLE TÉCNICO'!C787:C806,'🧂 INGREDIENTES'!$B$6:$C$500,2,0),0)*'⚙️ DETALLE TÉCNICO'!D787:D806/1000,IFERROR(VLOOKUP('⚙️ DETALLE TÉCNICO'!C787:C806,'🧂 INGREDIENTES'!$B$6:$C$500,2,0),0)*'⚙️ DETALLE TÉCNICO'!D787:D806),0)),0)) | F36: =IF('⚙️ DETALLE TÉCNICO'!M787="","",IFERROR(SUMPRODUCT(IFERROR('⚙️ DETALLE TÉCNICO'!G787:G791*'⚙️ DETALLE TÉCNICO'!H787:H791,0)),0)) | G36: =IF('⚙️ DETALLE TÉCNICO'!M787="","",IFERROR(SUM('⚙️ DETALLE TÉCNICO'!J787:J794),0)) | H36: =IF('⚙️ DETALLE TÉCNICO'!M787="","",E36+F36+G36) | I36: =IF('⚙️ DETALLE TÉCNICO'!M787="","",'⚙️ DETALLE TÉCNICO'!K787) | J36: =IF('⚙️ DETALLE TÉCNICO'!M787="","",H36*(1+I36))
A37: =ROW()-5 -> 32 | B37: =IF('⚙️ DETALLE TÉCNICO'!M807="","",'⚙️ DETALLE TÉCNICO'!M807) | C37: =IF('⚙️ DETALLE TÉCNICO'!M807="","",'⚙️ DETALLE TÉCNICO'!N807) | D37: =IF('⚙️ DETALLE TÉCNICO'!M807="","",'⚙️ DETALLE TÉCNICO'!L807) | E37: =IF('⚙️ DETALLE TÉCNICO'!M807="","",IFERROR(SUMPRODUCT(IFERROR(IF(('⚙️ DETALLE TÉCNICO'!E807:E826="KG")+('⚙️ DETALLE TÉCNICO'!E807:E826="LITRO")+('⚙️ DETALLE TÉCNICO'!E807:E826="GR")+('⚙️ DETALLE TÉCNICO'!E807:E826="ML"),IFERROR(VLOOKUP('⚙️ DETALLE TÉCNICO'!C807:C826,'🧂 INGREDIENTES'!$B$6:$C$500,2,0),0)*'⚙️ DETALLE TÉCNICO'!D807:D826/1000,IFERROR(VLOOKUP('⚙️ DETALLE TÉCNICO'!C807:C826,'🧂 INGREDIENTES'!$B$6:$C$500,2,0),0)*'⚙️ DETALLE TÉCNICO'!D807:D826),0)),0)) | F37: =IF('⚙️ DETALLE TÉCNICO'!M807="","",IFERROR(SUMPRODUCT(IFERROR('⚙️ DETALLE TÉCNICO'!G807:G811*'⚙️ DETALLE TÉCNICO'!H807:H811,0)),0)) | G37: =IF('⚙️ DETALLE TÉCNICO'!M807="","",IFERROR(SUM('⚙️ DETALLE TÉCNICO'!J807:J814),0)) | H37: =IF('⚙️ DETALLE TÉCNICO'!M807="","",E37+F37+G37) | I37: =IF('⚙️ DETALLE TÉCNICO'!M807="","",'⚙️ DETALLE TÉCNICO'!K807) | J37: =IF('⚙️ DETALLE TÉCNICO'!M807="","",H37*(1+I37))
A38: =ROW()-5 -> 33 | B38: =IF('⚙️ DETALLE TÉCNICO'!M827="","",'⚙️ DETALLE TÉCNICO'!M827) | C38: =IF('⚙️ DETALLE TÉCNICO'!M827="","",'⚙️ DETALLE TÉCNICO'!N827) | D38: =IF('⚙️ DETALLE TÉCNICO'!M827="","",'⚙️ DETALLE TÉCNICO'!L827) | E38: =IF('⚙️ DETALLE TÉCNICO'!M827="","",IFERROR(SUMPRODUCT(IFERROR(IF(('⚙️ DETALLE TÉCNICO'!E827:E846="KG")+('⚙️ DETALLE TÉCNICO'!E827:E846="LITRO")+('⚙️ DETALLE TÉCNICO'!E827:E846="GR")+('⚙️ DETALLE TÉCNICO'!E827:E846="ML"),IFERROR(VLOOKUP('⚙️ DETALLE TÉCNICO'!C827:C846,'🧂 INGREDIENTES'!$B$6:$C$500,2,0),0)*'⚙️ DETALLE TÉCNICO'!D827:D846/1000,IFERROR(VLOOKUP('⚙️ DETALLE TÉCNICO'!C827:C846,'🧂 INGREDIENTES'!$B$6:$C$500,2,0),0)*'⚙️ DETALLE TÉCNICO'!D827:D846),0)),0)) | F38: =IF('⚙️ DETALLE TÉCNICO'!M827="","",IFERROR(SUMPRODUCT(IFERROR('⚙️ DETALLE TÉCNICO'!G827:G831*'⚙️ DETALLE TÉCNICO'!H827:H831,0)),0)) | G38: =IF('⚙️ DETALLE TÉCNICO'!M827="","",IFERROR(SUM('⚙️ DETALLE TÉCNICO'!J827:J834),0)) | H38: =IF('⚙️ DETALLE TÉCNICO'!M827="","",E38+F38+G38) | I38: =IF('⚙️ DETALLE TÉCNICO'!M827="","",'⚙️ DETALLE TÉCNICO'!K827) | J38: =IF('⚙️ DETALLE TÉCNICO'!M827="","",H38*(1+I38))
A39: =ROW()-5 -> 34 | B39: =IF('⚙️ DETALLE TÉCNICO'!M847="","",'⚙️ DETALLE TÉCNICO'!M847) | C39: =IF('⚙️ DETALLE TÉCNICO'!M847="","",'⚙️ DETALLE TÉCNICO'!N847) | D39: =IF('⚙️ DETALLE TÉCNICO'!M847="","",'⚙️ DETALLE TÉCNICO'!L847) | E39: =IF('⚙️ DETALLE TÉCNICO'!M847="","",IFERROR(SUMPRODUCT(IFERROR(IF(('⚙️ DETALLE TÉCNICO'!E847:E866="KG")+('⚙️ DETALLE TÉCNICO'!E847:E866="LITRO")+('⚙️ DETALLE TÉCNICO'!E847:E866="GR")+('⚙️ DETALLE TÉCNICO'!E847:E866="ML"),IFERROR(VLOOKUP('⚙️ DETALLE TÉCNICO'!C847:C866,'🧂 INGREDIENTES'!$B$6:$C$500,2,0),0)*'⚙️ DETALLE TÉCNICO'!D847:D866/1000,IFERROR(VLOOKUP('⚙️ DETALLE TÉCNICO'!C847:C866,'🧂 INGREDIENTES'!$B$6:$C$500,2,0),0)*'⚙️ DETALLE TÉCNICO'!D847:D866),0)),0)) | F39: =IF('⚙️ DETALLE TÉCNICO'!M847="","",IFERROR(SUMPRODUCT(IFERROR('⚙️ DETALLE TÉCNICO'!G847:G851*'⚙️ DETALLE TÉCNICO'!H847:H851,0)),0)) | G39: =IF('⚙️ DETALLE TÉCNICO'!M847="","",IFERROR(SUM('⚙️ DETALLE TÉCNICO'!J847:J854),0)) | H39: =IF('⚙️ DETALLE TÉCNICO'!M847="","",E39+F39+G39) | I39: =IF('⚙️ DETALLE TÉCNICO'!M847="","",'⚙️ DETALLE TÉCNICO'!K847) | J39: =IF('⚙️ DETALLE TÉCNICO'!M847="","",H39*(1+I39))
A40: =ROW()-5 -> 35 | B40: =IF('⚙️ DETALLE TÉCNICO'!M867="","",'⚙️ DETALLE TÉCNICO'!M867) | C40: =IF('⚙️ DETALLE TÉCNICO'!M867="","",'⚙️ DETALLE TÉCNICO'!N867) | D40: =IF('⚙️ DETALLE TÉCNICO'!M867="","",'⚙️ DETALLE TÉCNICO'!L867) | E40: =IF('⚙️ DETALLE TÉCNICO'!M867="","",IFERROR(SUMPRODUCT(IFERROR(IF(('⚙️ DETALLE TÉCNICO'!E867:E886="KG")+('⚙️ DETALLE TÉCNICO'!E867:E886="LITRO")+('⚙️ DETALLE TÉCNICO'!E867:E886="GR")+('⚙️ DETALLE TÉCNICO'!E867:E886="ML"),IFERROR(VLOOKUP('⚙️ DETALLE TÉCNICO'!C867:C886,'🧂 INGREDIENTES'!$B$6:$C$500,2,0),0)*'⚙️ DETALLE TÉCNICO'!D867:D886/1000,IFERROR(VLOOKUP('⚙️ DETALLE TÉCNICO'!C867:C886,'🧂 INGREDIENTES'!$B$6:$C$500,2,0),0)*'⚙️ DETALLE TÉCNICO'!D867:D886),0)),0)) | F40: =IF('⚙️ DETALLE TÉCNICO'!M867="","",IFERROR(SUMPRODUCT(IFERROR('⚙️ DETALLE TÉCNICO'!G867:G871*'⚙️ DETALLE TÉCNICO'!H867:H871,0)),0)) | G40: =IF('⚙️ DETALLE TÉCNICO'!M867="","",IFERROR(SUM('⚙️ DETALLE TÉCNICO'!J867:J874),0)) | H40: =IF('⚙️ DETALLE TÉCNICO'!M867="","",E40+F40+G40) | I40: =IF('⚙️ DETALLE TÉCNICO'!M867="","",'⚙️ DETALLE TÉCNICO'!K867) | J40: =IF('⚙️ DETALLE TÉCNICO'!M867="","",H40*(1+I40))
A41: =ROW()-5 -> 36 | B41: =IF('⚙️ DETALLE TÉCNICO'!M887="","",'⚙️ DETALLE TÉCNICO'!M887) | C41: =IF('⚙️ DETALLE TÉCNICO'!M887="","",'⚙️ DETALLE TÉCNICO'!N887) | D41: =IF('⚙️ DETALLE TÉCNICO'!M887="","",'⚙️ DETALLE TÉCNICO'!L887) | E41: =IF('⚙️ DETALLE TÉCNICO'!M887="","",IFERROR(SUMPRODUCT(IFERROR(IF(('⚙️ DETALLE TÉCNICO'!E887:E906="KG")+('⚙️ DETALLE TÉCNICO'!E887:E906="LITRO")+('⚙️ DETALLE TÉCNICO'!E887:E906="GR")+('⚙️ DETALLE TÉCNICO'!E887:E906="ML"),IFERROR(VLOOKUP('⚙️ DETALLE TÉCNICO'!C887:C906,'🧂 INGREDIENTES'!$B$6:$C$500,2,0),0)*'⚙️ DETALLE TÉCNICO'!D887:D906/1000,IFERROR(VLOOKUP('⚙️ DETALLE TÉCNICO'!C887:C906,'🧂 INGREDIENTES'!$B$6:$C$500,2,0),0)*'⚙️ DETALLE TÉCNICO'!D887:D906),0)),0)) | F41: =IF('⚙️ DETALLE TÉCNICO'!M887="","",IFERROR(SUMPRODUCT(IFERROR('⚙️ DETALLE TÉCNICO'!G887:G891*'⚙️ DETALLE TÉCNICO'!H887:H891,0)),0)) | G41: =IF('⚙️ DETALLE TÉCNICO'!M887="","",IFERROR(SUM('⚙️ DETALLE TÉCNICO'!J887:J894),0)) | H41: =IF('⚙️ DETALLE TÉCNICO'!M887="","",E41+F41+G41) | I41: =IF('⚙️ DETALLE TÉCNICO'!M887="","",'⚙️ DETALLE TÉCNICO'!K887) | J41: =IF('⚙️ DETALLE TÉCNICO'!M887="","",H41*(1+I41))
...

Sheet ⚙️ DETALLE TÉCNICO
A2: ⚙️ DETALLE TÉCNICO DE RECETAS GUARDADAS
A3: Esta hoja es el motor del sistema. Cada fila es un ingrediente de una receta guardada. Los precios se recalculan automáticamente cuando actualizás la hoja INGREDIENTES.
A5: ID RECETA | C5: INGREDIENTE | F5: MANO DE OBRA | I5: GASTOS EXTRAS | K5: CONFIGURACIÓN
A6: N° | B6: SLOT | C6: INGREDIENTE | D6: CANTIDAD | E6: UNIDAD | F6: MO CONCEPTO | G6: MO HORAS | H6: MO $/HORA | I6: GE CONCEPTO | J6: GE MONTO | K6: % MARGEN | L6: PORCIONES | M6: NOMBRE RECETA | N6: FECHA
A7: 1 | B7: 1 | C7: Chocolinas | D7: 510 | E7: KG | F7: mano | G7: 2 | H7: 0 | I7: packaging - caja | J7: 90 | K7: 1 | M7: Chocotorta | N7: 46225.531
A8: 1 | B8: 2 | C8: Harina 0000 | D8: 500 | E8: KG | I8: packaging - base chica | J8: 35
A9: 1 | B9: 3 | C9: Manteca | D9: 100 | E9: KG
A10: 1 | B10: 4 | C10: Azúcar | E10: KG
A11: 1 | B11: 5
A12: 1 | B12: 6
A13: 1 | B13: 7
A14: 1 | B14: 8
A15: 1 | B15: 9
A16: 1 | B16: 10
A17: 1 | B17: 11
A18: 1 | B18: 12
A19: 1 | B19: 13
A20: 1 | B20: 14
A21: 1 | B21: 15
A22: 1 | B22: 16
... A46: 2 | B46: 20
A47: 3 | B47: 1 | C47: leche | D47: 1000 | E47: LITRO | F47: mano de obra | G47: 2 | H47: 1000 | I47: plato | K47: 0.6 | L47: 12 | M47: flan | N47: 46104.549
A48: 3 | B48: 2 | C48: Huevo | D48: 5 | E48: UNIDAD
A49: 3 | B49: 3 | C49: Azúcar | D49: 400 | E49: KG
A50: 3 | B50: 4
A51: 3 | B51: 5
A52: 3 | B52: 6
A53: 3 | B53: 7
A54: 3 | B54: 8
A55: 3 | B55: 9
A56: 3 | B56: 10
A57: 3 | B57: 11
A58: 3 | B58: 12
A59: 3 | B59: 13
A60: 3 | B60: 14
A61: 3 | B61: 15
... A66: 3 | B66: 20
A67: 4 | B67: 1 | C67: leche | D67: 600 | E67: LITRO | F67: mano de obra | G67: 0 | H67: 1000 | I67: molde | J67: 700 | K67: 1.5 | L67: 2 | M67: Rosca de Pascua | N67: 46104.583
A68: 4 | B68: 2 | C68: Huevo | D68: 6 | E68: UNIDAD | I68: caja | J68: 2500
A69: 4 | B69: 3 | C69: Azúcar | D69: 400 | E69: KG
...
